I'm sorry, but an uncaught exception occurred.

While running game code:
  File "game/Chapter_Four.rpy", line 199, in script
    menu:
  File "game/Chapter_Four.rpy", line 203, in <module>
    "Go get supplies" if janeD_dead == False and gone_to_supplies == False:
NameError: name 'gone_to_supplies' is not defined

-- Full Traceback ------------------------------------------------------------

Full traceback:
  File "game/Chapter_Four.rpy", line 199, in script
    menu:
  File "C:\Users\neoph\Desktop\renpy-7.3.5-sdk\renpy\ast.py", line 1628, in execute
    choice = renpy.exports.menu(choices, self.set, args, kwargs, item_arguments)
  File "C:\Users\neoph\Desktop\renpy-7.3.5-sdk\renpy\exports.py", line 956, in menu
    condition = renpy.python.py_eval(condition)
  File "C:\Users\neoph\Desktop\renpy-7.3.5-sdk\renpy\python.py", line 2059, in py_eval
    return py_eval_bytecode(code, globals, locals)
  File "C:\Users\neoph\Desktop\renpy-7.3.5-sdk\renpy\python.py", line 2052, in py_eval_bytecode
    return eval(bytecode, globals, locals)
  File "game/Chapter_Four.rpy", line 203, in <module>
    "Go get supplies" if janeD_dead == False and gone_to_supplies == False:
NameError: name 'gone_to_supplies' is not defined

Windows-8-6.2.9200
Ren'Py 7.3.5.606
Dracula 1.0
Sat May 30 20:27:04 2020
